Workbook
Name Slicer_Category: #N/A
Name Slicer_Month_name: #N/A
Name Slicer_Region: #N/A
Name Slicer_Year: #N/A

Sheet Dashboard

Sheet Pivot tables
A1: Sum of Sales | B1: Column Labels | H1: Performance per rep | I1: Column Labels | N1: Row Labels | O1: Sum of Sales
A2: Row Labels | B2: East | C2: North | D2: South | E2: West | F2: Grand Total | H2: Row Labels | I2: Active | J2: Left | K2: Grand Total | N2: 2020 | O2: 512939.72
A3: January | C3: 76269.209 | D3: 6442.7451 | F3: 82711.954 | H3: 2021 | I3: 23071.388 | J3: 1723.5019 | K3: 24794.89 | N3: 103 | O3: 107781.35
A4: February | C4: 68745.405 | D4: 5051.2498 | E4: 13309.103 | F4: 87105.758 | H4: 204 | I4: 5348.2648 | K4: 5348.2648 | N4: 105 | O4: 112890.65
A5: March | D5: 22920.817 | E5: 22572.681 | F5: 45493.498 | H5: 205 | I5: 8076.1624 | K5: 8076.1624 | N5: 106 | O5: 85185.175
A6: April | B6: 32723.528 | D6: 36693.145 | E6: 24568.228 | F6: 93984.9 | H6: 206 | I6: 2546.9415 | K6: 2546.9415 | N6: 108 | O6: 96913.949
A7: May | B7: 31487.698 | C7: 23930.801 | D7: 54263.964 | E7: 7047.3888 | F7: 116729.85 | H7: 208 | I7: 1532.5465 | K7: 1532.5465 | N7: 110 | O7: 110168.59
A8: June | B8: 41609.585 | C8: 40447.69 | D8: 57027.793 | E8: 16536.616 | F8: 155621.68 | H8: 209 | J8: 1723.5019 | K8: 1723.5019 | N8: 2021 | O8: 94000.471
A9: July | B9: 1960.539 | C9: 42827.764 | D9: 44955.495 | E9: 17090.454 | F9: 106834.25 | H9: 210 | I9: 2173.0279 | K9: 2173.0279 | N9: 104 | O9: 94000.471
A10: August | C10: 19461.313 | D10: 12254.72 | E10: 20349.019 | F10: 52065.052 | H10: 213 | I10: 2016.4564 | K10: 2016.4564 | N10: 2022 | O10: 445958.17
A11: September | C11: 15078.178 | D11: 22555.937 | F11: 37634.115 | H11: 218 | I11: 1377.9883 | K11: 1377.9883 | N11: 101 | O11: 100108.59
A12: October | C12: 43039.677 | D12: 11485.228 | F12: 54524.906 | H12: 2022 | I12: 44358.37 | J12: 18588.27 | K12: 62946.64 | N12: 102 | O12: 122057.22
A13: November | C13: 68043.596 | D13: 9079.4735 | F13: 77123.07 | H13: 201 | I13: 1915.1164 | K13: 1915.1164 | N13: 107 | O13: 102318.88
A14: December | C14: 133723.59 | D14: 9345.7288 | F14: 143069.32 | H14: 202 | I14: 4548.8799 | K14: 4548.8799 | N14: 109 | O14: 121473.49
A15: Grand Total | B15: 107781.35 | C15: 531567.22 | D15: 292076.3 | E15: 121473.49 | F15: 1052898.4 | H15: 203 | I15: 1863.8679 | K15: 1863.8679 | N15: Grand Total | O15: 1052898.4
H16: 207 | I16: 8981.7792 | K16: 8981.7792
H17: 211 | I17: 4209.0753 | K17: 4209.0753
H18: 212 | I18: 2015.2019 | K18: 2015.2019
H19: 214 | I19: 4774.526 | K19: 4774.526
H20: 215 | I20: 4317.4978 | K20: 4317.4978
H21: 216 | J21: 9407.5541 | K21: 9407.5541
H22: 217 | J22: 9180.716 | K22: 9180.716
H23: 219 | I23: 10171.435 | K23: 10171.435
H24: 220 | I24: 1560.9909 | K24: 1560.9909
H25: Grand Total | I25: 67429.758 | J25: 20311.772 | K25: 87741.53
N27: Row Labels | O27: Sum of Sales
H28: Row Labels | I28: Sum of Profit | N28: 101 | O28: 100108.59
A29: Row Labels | B29: Sum of Sales | C29: Sum of Profit | H29: 307 | I29: 12465.27 | N29: 102 | O29: 122057.22
A30: Clothing | B30: 167303.69 | C30: 9569.8143 | H30: 311 | I30: 10193.215 | N30: 103 | O30: 107781.35
A31: Electronics | B31: 197546.8 | C31: 18547.442 | H31: 319 | I31: 9903.5738 | N31: 104 | O31: 94000.471
A32: Home & Kitchen | B32: 363865.02 | C32: 21511.831 | H32: 301 | I32: 9204.4925 | N32: 105 | O32: 112890.65
A33: Toys | B33: 324182.84 | C33: 23715.573 | H33: 317 | I33: 8533.7468 | N33: 106 | O33: 85185.175
A34: Grand Total | B34: 1052898.4 | C34: 73344.66 | H34: 310 | I34: 8521.7797 | N34: 107 | O34: 102318.88
H35: 306 | I35: 6231.1019 | N35: 108 | O35: 96913.949
H36: 303 | I36: 5832.0436 | N36: 109 | O36: 121473.49
H37: 312 | I37: 5751.2325 | N37: 110 | O37: 110168.59
H38: 318 | I38: 4864.2956 | N38: Grand Total | O38: 1052898.4
H39: 313 | I39: 3033.951
H40: 309 | I40: 2814.3777
H41: 305 | I41: 1664.276
...

Sheet SalesData
A1: Date | B1: StoreID | C1: Opening Date | D1: RepID | E1: Joining date | F1: Status | G1: ProductID | H1: Category | I1: Subcategory | J1: Quantity | K1: Costprice | L1: UnitPrice | M1: Discount% | N1: Region | O1: Saleprice | P1: Sales | Q1: Profit | R1: Year | S1: Month | T1: Month name
A2: 44301 | B2: 104 | C2: =_xlfn.XLOOKUP(B2,Stores!A:A,Stores!E:E) -> 44297 | D2: 209 | E2: =_xlfn.XLOOKUP(D2,SalesReps!A:A,SalesReps!D:D) -> 44218 | F2: =_xlfn.XLOOKUP(Table1[[#This Row],[RepID]],SalesReps!A:A,SalesReps!E:E) -> Left | G2: 305 | H2: =_xlfn.XLOOKUP(Table1[[#This Row],[ProductID]],Products!A:A,Products!B:B) -> Electronics | I2: =_xlfn.XLOOKUP(Table1[[#This Row],[ProductID]],Products!A:A,Products!C:C) -> Accessories | J2: 2 | K2: =_xlfn.XLOOKUP(Table1[[#This Row],[ProductID]],Products!A:A,Products!E:E) -> 275.32 | L2: 305.91 | M2: 0.1 | N2: South | O2: =L2*(1-M2) -> 275.319 | P2: =O2*J2 -> 550.638 | Q2: =Table1[[#This Row],[Quantity]]*(Table1[[#This Row],[Saleprice]]-Table1[[#This Row],[Costprice]]) -> -0.002 | R2: =YEAR(A2) -> 2021 | S2: =MONTH(A2) -> 4 | T2: =TEXT(A2,"MMMM") -> April
A3: 44303 | B3: 104 | C3: =_xlfn.XLOOKUP(B3,Stores!A:A,Stores!E:E) -> 44297 | D3: 209 | E3: =_xlfn.XLOOKUP(D3,SalesReps!A:A,SalesReps!D:D) -> 44218 | F3: =_xlfn.XLOOKUP(Table1[[#This Row],[RepID]],SalesReps!A:A,SalesReps!E:E) -> Left | G3: 301 | H3: =_xlfn.XLOOKUP(Table1[[#This Row],[ProductID]],Products!A:A,Products!B:B) -> Electronics | I3: =_xlfn.XLOOKUP(Table1[[#This Row],[ProductID]],Products!A:A,Products!C:C) -> Mobiles | J3: 2 | K3: =_xlfn.XLOOKUP(Table1[[#This Row],[ProductID]],Products!A:A,Products!E:E) -> 159.16 | L3: 201.7 | M3: 0.24 | N3: South | O3: =L3*(1-M3) -> 153.292 | P3: =O3*J3 -> 306.584 | Q3: =Table1[[#This Row],[Quantity]]*(Table1[[#This Row],[Saleprice]]-Table1[[#This Row],[Costprice]]) -> -11.736 | R3: =YEAR(A3) -> 2021 | S3: =MONTH(A3) -> 4 | T3: =TEXT(A3,"MMMM") -> April
A4: 44304 | B4: 104 | C4: =_xlfn.XLOOKUP(B4,Stores!A:A,Stores!E:E) -> 44297 | D4: 209 | E4: =_xlfn.XLOOKUP(D4,SalesReps!A:A,SalesReps!D:D) -> 44218 | F4: =_xlfn.XLOOKUP(Table1[[#This Row],[RepID]],SalesReps!A:A,SalesReps!E:E) -> Left | G4: 301 | H4: =_xlfn.XLOOKUP(Table1[[#This Row],[ProductID]],Products!A:A,Products!B:B) -> Electronics | I4: =_xlfn.XLOOKUP(Table1[[#This Row],[ProductID]],Products!A:A,Products!C:C) -> Mobiles | J4: 1 | K4: =_xlfn.XLOOKUP(Table1[[#This Row],[ProductID]],Products!A:A,Products!E:E) -> 159.16 | L4: 201.7 | M4: 0.24 | N4: South | O4: =L4*(1-M4) -> 153.292 | P4: =O4*J4 -> 153.292 | Q4: =Table1[[#This Row],[Quantity]]*(Table1[[#This Row],[Saleprice]]-Table1[[#This Row],[Costprice]]) -> -5.868 | R4: =YEAR(A4) -> 2021 | S4: =MONTH(A4) -> 4 | T4: =TEXT(A4,"MMMM") -> April
A5: 44304 | B5: 104 | C5: =_xlfn.XLOOKUP(B5,Stores!A:A,Stores!E:E) -> 44297 | D5: 209 | E5: =_xlfn.XLOOKUP(D5,SalesReps!A:A,SalesReps!D:D) -> 44218 | F5: =_xlfn.XLOOKUP(Table1[[#This Row],[RepID]],SalesReps!A:A,SalesReps!E:E) -> Left | G5: 314 | H5: =_xlfn.XLOOKUP(Table1[[#This Row],[ProductID]],Products!A:A,Products!B:B) -> Clothing | I5: =_xlfn.XLOOKUP(Table1[[#This Row],[ProductID]],Products!A:A,Products!C:C) -> Kids | J5: 4 | K5: =_xlfn.XLOOKUP(Table1[[#This Row],[ProductID]],Products!A:A,Products!E:E) -> 276.47 | L5: 298.98 | M5: 0.07 | N5: South | O5: =L5*(1-M5) -> 278.0514 | P5: =O5*J5 -> 1112.2056 | Q5: =Table1[[#This Row],[Quantity]]*(Table1[[#This Row],[Saleprice]]-Table1[[#This Row],[Costprice]]) -> 6.3256 | R5: =YEAR(A5) -> 2021 | S5: =MONTH(A5) -> 4 | T5: =TEXT(A5,"MMMM") -> April
A6: 44307 | B6: 104 | C6: =_xlfn.XLOOKUP(B6,Stores!A:A,Stores!E:E) -> 44297 | D6: 209 | E6: =_xlfn.XLOOKUP(D6,SalesReps!A:A,SalesReps!D:D) -> 44218 | F6: =_xlfn.XLOOKUP(Table1[[#This Row],[RepID]],SalesReps!A:A,SalesReps!E:E) -> Left | G6: 306 | H6: =_xlfn.XLOOKUP(Table1[[#This Row],[ProductID]],Products!A:A,Products!B:B) -> Clothing | I6: =_xlfn.XLOOKUP(Table1[[#This Row],[ProductID]],Products!A:A,Products!C:C) -> Men | J6: 5 | K6: =_xlfn.XLOOKUP(Table1[[#This Row],[ProductID]],Products!A:A,Products!E:E) -> 185.69 | L6: 241.13 | M6: 0.14 | N6: South | O6: =L6*(1-M6) -> 207.3718 | P6: =O6*J6 -> 1036.859 | Q6: =Table1[[#This Row],[Quantity]]*(Table1[[#This Row],[Saleprice]]-Table1[[#This Row],[Costprice]]) -> 108.409 | R6: =YEAR(A6) -> 2021 | S6: =MONTH(A6) -> 4 | T6: =TEXT(A6,"MMMM") -> April
A7: 44308 | B7: 104 | C7: =_xlfn.XLOOKUP(B7,Stores!A:A,Stores!E:E) -> 44297 | D7: 209 | E7: =_xlfn.XLOOKUP(D7,SalesReps!A:A,SalesReps!D:D) -> 44218 | F7: =_xlfn.XLOOKUP(Table1[[#This Row],[RepID]],SalesReps!A:A,SalesReps!E:E) -> Left | G7: 311 | H7: =_xlfn.XLOOKUP(Table1[[#This Row],[ProductID]],Products!A:A,Products!B:B) -> Home & Kitchen | I7: =_xlfn.XLOOKUP(Table1[[#This Row],[ProductID]],Products!A:A,Products!C:C) -> Furniture | J7: 3 | K7: =_xlfn.XLOOKUP(Table1[[#This Row],[ProductID]],Products!A:A,Products!E:E) -> 16.23 | L7: 46.74 | M7: 0.15 | N7: South | O7: =L7*(1-M7) -> 39.729 | P7: =O7*J7 -> 119.187 | Q7: =Table1[[#This Row],[Quantity]]*(Table1[[#This Row],[Saleprice]]-Table1[[#This Row],[Costprice]]) -> 70.497 | R7: =YEAR(A7) -> 2021 | S7: =MONTH(A7) -> 4 | T7: =TEXT(A7,"MMMM") -> April
A8: 44315 | B8: 104 | C8: =_xlfn.XLOOKUP(B8,Stores!A:A,Stores!E:E) -> 44297 | D8: 209 | E8: =_xlfn.XLOOKUP(D8,SalesReps!A:A,SalesReps!D:D) -> 44218 | F8: =_xlfn.XLOOKUP(Table1[[#This Row],[RepID]],SalesReps!A:A,SalesReps!E:E) -> Left | G8: 315 | H8: =_xlfn.XLOOKUP(Table1[[#This Row],[ProductID]],Products!A:A,Products!B:B) -> Toys | I8: =_xlfn.XLOOKUP(Table1[[#This Row],[ProductID]],Products!A:A,Products!C:C) -> Board Games | J8: 7 | K8: =_xlfn.XLOOKUP(Table1[[#This Row],[ProductID]],Products!A:A,Products!E:E) -> 247.9 | L8: 285.38 | M8: 0.07 | N8: South | O8: =L8*(1-M8) -> 265.4034 | P8: =O8*J8 -> 1857.8238 | Q8: =Table1[[#This Row],[Quantity]]*(Table1[[#This Row],[Saleprice]]-Table1[[#This Row],[Costprice]]) -> 122.5238 | R8: =YEAR(A8) -> 2021 | S8: =MONTH(A8) -> 4 | T8: =TEXT(A8,"MMMM") -> April
A9: 44316 | B9: 104 | C9: =_xlfn.XLOOKUP(B9,Stores!A:A,Stores!E:E) -> 44297 | D9: 209 | E9: =_xlfn.XLOOKUP(D9,SalesReps!A:A,SalesReps!D:D) -> 44218 | F9: =_xlfn.XLOOKUP(Table1[[#This Row],[RepID]],SalesReps!A:A,SalesReps!E:E) -> Left | G9: 317 | H9: =_xlfn.XLOOKUP(Table1[[#This Row],[ProductID]],Products!A:A,Products!B:B) -> Toys | I9: =_xlfn.XLOOKUP(Table1[[#This Row],[ProductID]],Products!A:A,Products!C:C) -> Educational | J9: 2 | K9: =_xlfn.XLOOKUP(Table1[[#This Row],[ProductID]],Products!A:A,Products!E:E) -> 77.61 | L9: 141.34 | M9: 0.12 | N9: South | O9: =L9*(1-M9) -> 124.3792 | P9: =O9*J9 -> 248.7584 | Q9: =Table1[[#This Row],[Quantity]]*(Table1[[#This Row],[Saleprice]]-Table1[[#This Row],[Costprice]]) -> 93.5384 | R9: =YEAR(A9) -> 2021 | S9: =MONTH(A9) -> 4 | T9: =TEXT(A9,"MMMM") -> April
A10: 44317 | B10: 104 | C10: =_xlfn.XLOOKUP(B10,Stores!A:A,Stores!E:E) -> 44297 | D10: 209 | E10: =_xlfn.XLOOKUP(D10,SalesReps!A:A,SalesReps!D:D) -> 44218 | F10: =_xlfn.XLOOKUP(Table1[[#This Row],[RepID]],SalesReps!A:A,SalesReps!E:E) -> Left | G10: 306 | H10: =_xlfn.XLOOKUP(Table1[[#This Row],[ProductID]],Products!A:A,Products!B:B) -> Clothing | I10: =_xlfn.XLOOKUP(Table1[[#This Row],[ProductID]],Products!A:A,Products!C:C) -> Men | J10: 6 | K10: =_xlfn.XLOOKUP(Table1[[#This Row],[ProductID]],Products!A:A,Products!E:E) -> 185.69 | L10: 241.13 | M10: 0.14 | N10: South | O10: =L10*(1-M10) -> 207.3718 | P10: =O10*J10 -> 1244.2308 | Q10: =Table1[[#This Row],[Quantity]]*(Table1[[#This Row],[Saleprice]]-Table1[[#This Row],[Costprice]]) -> 130.0908 | R10: =YEAR(A10) -> 2021 | S10: =MONTH(A10) -> 5 | T10: =TEXT(A10,"MMMM") -> May
A11: 44318 | B11: 104 | C11: =_xlfn.XLOOKUP(B11,Stores!A:A,Stores!E:E) -> 44297 | D11: 209 | E11: =_xlfn.XLOOKUP(D11,SalesReps!A:A,SalesReps!D:D) -> 44218 | F11: =_xlfn.XLOOKUP(Table1[[#This Row],[RepID]],SalesReps!A:A,SalesReps!E:E) -> Left | G11: 307 | H11: =_xlfn.XLOOKUP(Table1[[#This Row],[ProductID]],Products!A:A,Products!B:B) -> Toys | I11: =_xlfn.XLOOKUP(Table1[[#This Row],[ProductID]],Products!A:A,Products!C:C) -> Outdoor | J11: 8 | K11: =_xlfn.XLOOKUP(Table1[[#This Row],[ProductID]],Products!A:A,Products!E:E) -> 15.17 | L11: 97.07 | M11: 0.12 | N11: South | O11: =L11*(1-M11) -> 85.4216 | P11: =O11*J11 -> 683.3728 | Q11: =Table1[[#This Row],[Quantity]]*(Table1[[#This Row],[Saleprice]]-Table1[[#This Row],[Costprice]]) -> 562.0128 | R11: =YEAR(A11) -> 2021 | S11: =MONTH(A11) -> 5 | T11: =TEXT(A11,"MMMM") -> May
A12: 44328 | B12: 104 | C12: =_xlfn.XLOOKUP(B12,Stores!A:A,Stores!E:E) -> 44297 | D12: 209 | E12: =_xlfn.XLOOKUP(D12,SalesReps!A:A,SalesReps!D:D) -> 44218 | F12: =_xlfn.XLOOKUP(Table1[[#This Row],[RepID]],SalesReps!A:A,SalesReps!E:E) -> Left | G12: 311 | H12: =_xlfn.XLOOKUP(Table1[[#This Row],[ProductID]],Products!A:A,Products!B:B) -> Home & Kitchen | I12: =_xlfn.XLOOKUP(Table1[[#This Row],[ProductID]],Products!A:A,Products!C:C) -> Furniture | J12: 4 | K12: =_xlfn.XLOOKUP(Table1[[#This Row],[ProductID]],Products!A:A,Products!E:E) -> 16.23 | L12: 46.74 | M12: 0.15 | N12: South | O12: =L12*(1-M12) -> 39.729 | P12: =O12*J12 -> 158.916 | Q12: =Table1[[#This Row],[Quantity]]*(Table1[[#This Row],[Saleprice]]-Table1[[#This Row],[Costprice]]) -> 93.996 | R12: =YEAR(A12) -> 2021 | S12: =MONTH(A12) -> 5 | T12: =TEXT(A12,"MMMM") -> May
A13: 44328 | B13: 104 | C13: =_xlfn.XLOOKUP(B13,Stores!A:A,Stores!E:E) -> 44297 | D13: 209 | E13: =_xlfn.XLOOKUP(D13,SalesReps!A:A,SalesReps!D:D) -> 44218 | F13: =_xlfn.XLOOKUP(Table1[[#This Row],[RepID]],SalesReps!A:A,SalesReps!E:E) -> Left | G13: 311 | H13: =_xlfn.XLOOKUP(Table1[[#This Row],[ProductID]],Products!A:A,Products!B:B) -> Home & Kitchen | I13: =_xlfn.XLOOKUP(Table1[[#This Row],[ProductID]],Products!A:A,Products!C:C) -> Furniture | J13: 1 | K13: =_xlfn.XLOOKUP(Table1[[#This Row],[ProductID]],Products!A:A,Products!E:E) -> 16.23 | L13: 46.74 | M13: 0.15 | N13: South | O13: =L13*(1-M13) -> 39.729 | P13: =O13*J13 -> 39.729 | Q13: =Table1[[#This Row],[Quantity]]*(Table1[[#This Row],[Saleprice]]-Table1[[#This Row],[Costprice]]) -> 23.499 | R13: =YEAR(A13) -> 2021 | S13: =MONTH(A13) -> 5 | T13: =TEXT(A13,"MMMM") -> May
... A1001: 44983 | B1001: 110 | C1001: =_xlfn.XLOOKUP(B1001,Stores!A:A,Stores!E:E) -> 44174 | D1001: 217 | E1001: =_xlfn.XLOOKUP(D1001,SalesReps!A:A,SalesReps!D:D) -> 44896 | F1001: =_xlfn.XLOOKUP(Table1[[#This Row],[RepID]],SalesReps!A:A,SalesReps!E:E) -> Left | G1001: 317 | H1001: =_xlfn.XLOOKUP(Table1[[#This Row],[ProductID]],Products!A:A,Products!B:B) -> Toys | I1001: =_xlfn.XLOOKUP(Table1[[#This Row],[ProductID]],Products!A:A,Products!C:C) -> Educational | J1001: 2 | K1001: =_xlfn.XLOOKUP(Table1[[#This Row],[ProductID]],Products!A:A,Products!E:E) -> 77.61 | L1001: 122.31 | M1001: 0.24 | N1001: North | O1001: =L1001*(1-M1001) -> 92.9556 | P1001: =O1001*J1001 -> 185.9112 | Q1001: =Table1[[#This Row],[Quantity]]*(Table1[[#This Row],[Saleprice]]-Table1[[#This Row],[Costprice]]) -> 30.6912 | R1001: =YEAR(A1001) -> 2023 | S1001: =MONTH(A1001) -> 2 | T1001: =TEXT(A1001,"MMMM") -> February

Sheet Products
A1: ProductID | B1: Category | C1: SubCategory | D1: Brand | E1: CostPrice
A2: 301 | B2: Electronics | C2: Mobiles | D2: BrandA | E2: 159.16
A3: 302 | B3: Toys | C3: Outdoor | D3: BrandD | E3: 393.46
A4: 303 | B4: Home & Kitchen | C4: Furniture | D4: BrandC | E4: 192.04
A5: 304 | B5: Home & Kitchen | C5: Furniture | D5: BrandC | E5: 345.38
A6: 305 | B6: Electronics | C6: Accessories | D6: BrandB | E6: 275.32
A7: 306 | B7: Clothing | C7: Men | D7: BrandD | E7: 185.69
A8: 307 | B8: Toys | C8: Outdoor | D8: BrandB | E8: 15.17
A9: 308 | B9: Home & Kitchen | C9: Furniture | D9: BrandB | E9: 377.46
A10: 309 | B10: Electronics | C10: Laptops | D10: BrandD | E10: 229.68
A11: 310 | B11: Home & Kitchen | C11: Furniture | D11: BrandB | E11: 160.31
A12: 311 | B12: Home & Kitchen | C12: Furniture | D12: BrandD | E12: 16.23
A13: 312 | B13: Toys | C13: Board Games | D13: BrandD | E13: 100.05
... A21: 320 | B21: Toys | C21: Outdoor | D21: BrandD | E21: 304.59

Sheet Stores
A1: StoreID | B1: StoreName | C1: Region | D1: City | E1: OpeningDate
A2: 101 | B2: Store_101 | C2: North | D2: City_101 | E2: 44691
A3: 102 | B3: Store_102 | C3: North | D3: City_102 | E3: 44875
A4: 103 | B4: Store_103 | C4: East | D4: City_103 | E4: 43952
A5: 104 | B5: Store_104 | C5: South | D5: City_104 | E5: 44297
A6: 105 | B6: Store_105 | C6: South | D6: City_105 | E6: 44161
A7: 106 | B7: Store_106 | C7: South | D7: City_106 | E7: 43918
A8: 107 | B8: Store_107 | C8: North | D8: City_107 | E8: 44702
A9: 108 | B9: Store_108 | C9: North | D9: City_108 | E9: 43961
A10: 109 | B10: Store_109 | C10: West | D10: City_109 | E10: 44600
A11: 110 | B11: Store_110 | C11: North | D11: City_110 | E11: 44174

Sheet SalesReps
A1: RepID | B1: RepName | C1: StoreID | D1: JoinDate | E1: Status
A2: 201 | B2: Rep_201 | C2: 101 | D2: 44688 | E2: Active
A3: 202 | B3: Rep_202 | C3: 104 | D3: 44610 | E3: Active
A4: 203 | B4: Rep_203 | C4: 101 | D4: 44582 | E4: Active
A5: 204 | B5: Rep_204 | C5: 109 | D5: 44388 | E5: Active
A6: 205 | B6: Rep_205 | C6: 108 | D6: 44473 | E6: Active
A7: 206 | B7: Rep_206 | C7: 101 | D7: 44357 | E7: Active
A8: 207 | B8: Rep_207 | C8: 103 | D8: 44656 | E8: Active
A9: 208 | B9: Rep_208 | C9: 106 | D9: 44510 | E9: Active
A10: 209 | B10: Rep_209 | C10: 104 | D10: 44218 | E10: Left
A11: 210 | B11: Rep_210 | C11: 106 | D11: 44449 | E11: Active
A12: 211 | B12: Rep_211 | C12: 107 | D12: 44757 | E12: Active
A13: 212 | B13: Rep_212 | C13: 106 | D13: 44671 | E13: Active
... A21: 220 | B21: Rep_220 | C21: 104 | D21: 44759 | E21: Active

Sheet ProductStorePricing
A1: ProductID | B1: StoreID | C1: UnitPrice | D1: Discount%
A2: 301 | B2: 101 | C2: 204.55 | D2: 0.09
A3: 301 | B3: 102 | C3: 218.09 | D3: 0.06
A4: 301 | B4: 103 | C4: 244.18 | D4: 0.14
A5: 301 | B5: 104 | C5: 201.7 | D5: 0.24
A6: 301 | B6: 105 | C6: 233.25 | D6: 0.12
A7: 301 | B7: 106 | C7: 218.35 | D7: 0.15
A8: 301 | B8: 107 | C8: 255.47 | D8: 0.22
A9: 301 | B9: 108 | C9: 235.16 | D9: 0.16
A10: 301 | B10: 109 | C10: 219.9 | D10: 0.24
A11: 301 | B11: 110 | C11: 221.83 | D11: 0.11
A12: 302 | B12: 101 | C12: 426.61 | D12: 0.08
A13: 302 | B13: 102 | C13: 399.95 | D13: 0.13
... A201: 320 | B201: 110 | C201: 332.08 | D201: 0.23
